Workbook
Name _Account_Lookup: 'Account Table'!$E$1:$E$500

Sheet Cover
A1: ='Yardi Report'!A1 -> SS of Crown Point West LLC (cpwest)
A2: Date | B2: 45930
A5: G/L Description | B5: Amount | C5: Reconciled? | D5: Notes
A6: Pre-Paid Insurance | B6: {=INDIRECT("'"&A6&"'!G5")} -> 460.54 | C6: {=IF(INDIRECT("'"&A6&"'!H5")="","Yes",INDIRECT("'"&A6&"'!H5"))} -> Yes
A7: Pre-Paid Expenses - Other | B7: {=INDIRECT("'"&A7&"'!G5")} -> 0 | C7: {=IF(INDIRECT("'"&A7&"'!H5")="","Yes",INDIRECT("'"&A7&"'!H5"))} -> Yes
A8: Real Estate Tax Accrual | B8: {=INDIRECT("'"&A8&"'!G5")} -> -130665.65 | C8: {=IF(INDIRECT("'"&A8&"'!H5")="","Yes",INDIRECT("'"&A8&"'!H5"))} -> Yes
A9: Sales Tax Collected | B9: {=INDIRECT("'"&A9&"'!G5")} -> -302.44 | C9: {=IF(INDIRECT("'"&A9&"'!H5")="","Yes",INDIRECT("'"&A9&"'!H5"))} -> Out of Balance
A10: Interest Accrual | B10: {=INDIRECT("'"&A10&"'!G5")} -> -23796.06 | C10: {=IF(INDIRECT("'"&A10&"'!H5")="","Yes",INDIRECT("'"&A10&"'!H5"))} -> Yes
A11: Expense Accrual | B11: {=INDIRECT("'"&A11&"'!G5")} -> 4029.21 | C11: {=IF(INDIRECT("'"&A11&"'!H5")="","Yes",INDIRECT("'"&A11&"'!H5"))} -> Out of Balance
A17: Completed by: | B17: RM
A18: Date Completed: | B18: 45944

Sheet Pre-Paid Insurance
A1: =Cover!A1 -> SS of Crown Point West LLC (cpwest)
A2: =Cover!B2 -> 45930
A3: 1350-0001 Pre-Paid Insurance
E5: Account Balance | G5: =INDEX('Yardi Report'!A:E,MATCH(LEFT(A3,9),'Yardi Report'!A:A,0),3) -> 460.54 | H5: =IF(G52=0,"","Out of Balance")
B7: Date | C7: Period | E7: G/L Description | G7: Amount | H7: Notes
B9: 44854 | C9: =B9 -> 44854 | E9: PFG Insurance payment | F9: 11494.82
B10: 44895 | C10: =B10 -> 44895 | E10: Expense Distribution | F10: -928.14
B11: 44921 | C11: =B11 -> 44921 | E11: Expense Distribution | F11: -928.14
B12: 44951 | C12: =B12 -> 44951 | E12: Expense Distribution | F12: -928.14
B13: 44984 | C13: =B13 -> 44984 | E13: Expense Distribution | F13: -928.14
B14: 45009 | C14: =B14 -> 45009 | E14: Expense Distribution | F14: -928.14
B15: 45041 | C15: =B15 -> 45041 | E15: Expense Distribution | F15: -928.14
B16: 45072 | C16: =B16 -> 45072 | E16: Expense Distribution | F16: -928.14
B17: 45103 | C17: =B17 -> 45103 | E17: Expense Distribution | F17: -928.14
B18: 45138 | C18: =B18 -> 45138 | E18: Expense Distribution | F18: -928.14
B19: 45163 | C19: =B19 -> 45163 | E19: Expense Distribution | F19: -928.14
B20: 45198 | C20: =B20 -> 45198 | E20: Expense Distribution | F20: -928.14
B21: 45226 | C21: =B21 -> 45226 | E21: Expense Distribution | F21: -928.14
E22: Left to Distribute | G22: =SUM(F9:F21) -> 357.14 | H22: Ammortization miscalculated
B24: 45473 | C24: =B24 -> 45473 | E24: PFG Insurance payment | F24: 1093.84
B25: 45533 | C25: 45474 | E25: Expense Distribution | F25: -99.44 | H25: July Expense
B26: 45535 | C26: =B26 -> 45535 | E26: Expense Distribution | F26: -99.44
B27: 45562 | C27: =B27 -> 45562 | E27: Expense Distribution | F27: -99.44
B28: 45596 | C28: =B28 -> 45596 | E28: Expense Distribution | F28: -99.44
B29: 45625 | C29: =B29 -> 45625 | E29: Expense Distribution | F29: -99.44
B30: 45657 | C30: =B30 -> 45657 | E30: Expense Distribution | F30: -99.44
B31: 45688 | C31: =B31 -> 45688 | E31: Expense Distribution | F31: -99.44
B32: 45716 | C32: =B32 -> 45716 | E32: Expense Distribution | F32: -99.44
B33: 45747 | C33: =B33 -> 45747 | E33: Expense Distribution | F33: -99.44
E34: Expense Distribution | F34: -99.44
E35: Left to Distribute | G35: =SUM(F24:F34) -> 99.44
B37: 45610 | C37: =B37 -> 45610 | E37: PFG Insurance payment | F37: 13158
B38: 45625 | C38: =B38 -> 45625 | E38: Expense Distribution | F38: -1096.17
B39: 45657 | C39: =B39 -> 45657 | E39: Expense Distribution | F39: -1096.17
B40: 45688 | C40: =B40 -> 45688 | E40: Expense Distribution | F40: -1096.17
B41: 45716 | C41: =B41 -> 45716 | E41: Expense Distribution | F41: -1096.17
B42: 45747 | C42: =B42 -> 45747 | E42: Expense Distribution | F42: -1096.17
B43: 45777 | C43: =B43 -> 45777 | E43: Expense Distribution | F43: -1096.17
B44: 45808 | C44: 45778 | E44: Expense Distribution | F44: -1096.17
B45: 45838 | C45: 45809 | E45: Expense Distribution | F45: -1096.17
...

Sheet 1350-9000 Pre-Paid Expenses Oth
A1: =Cover!A1 -> SS of Crown Point West LLC (cpwest)
A2: =Cover!B2 -> 45930
A3: 1350-9000 Pre-Paid Expenses - Other
D5: Account Balance | F5: =INDEX('Yardi Report'!A:E,MATCH(LEFT(A3,9),'Yardi Report'!A:A,0),3) -> #N/A
B7: Date | D7: G/L Description | F7: Amount | G7: Notes
D25: Variance | F25: =ROUND(F5-SUM(F9:F24),2) -> #N/A | G25: =IF(F25=0,"","Out of Balance") -> #N/A

Sheet Real Estate Tax Accrual
A1: =Cover!A1 -> SS of Crown Point West LLC (cpwest)
A2: =Cover!B2 -> 45930
A3: 2305-0000 Real Estate Tax Accrual
E5: Account Balance | G5: =-INDEX('Yardi Report'!A:E,MATCH(LEFT(A3,9),'Yardi Report'!A:A,0),3) -> -130665.65 | H5: =IF(G66=0,"","Out of Balance")
B7: Date | C7: Period | E7: G/L Description | G7: Amount | H7: Notes
B9: 44854 | C9: 44835 | E9: Opening Entry | F9: =-14182.54-17250.26-2475.38-2020.25 -> -35928.43 | H9: 1/1/2022 to 10/20/2022
B10: 44864 | C10: 44805 | E10: Monthly Tax Accrual | F10: =-1477.35-1796.9-257.85-210.44 -> -3742.54
B11: 44895 | C11: 44835 | E11: Monthly Tax Accrual | F11: =-1477.35-1796.9-257.85-210.44 -> -3742.54
B12: 44925 | C12: 44866 | E12: Monthly Tax Accrual | F12: =-1477.35-1796.9-257.85-210.44 -> -3742.54
B13: 45047 | C13: 45047 | E13: Tax Payment | F13: =1420.02+1711.62+9380.86+11506.9 -> 24019.4 | H13: 2022 1st Installment Pin# 45-16-05-487-002.000-042
B14: 45231 | C14: 45231 | E14: Tax Payment | F14: =1060.02+1351.62+9200.86+11326.9 -> 22939.4 | H14: 2022 2nd Installment Pin# 45-16-05-487-002.000-042
E15: (Over)/Under Accrual | G15: =SUM(F9:F14) -> -197.25
B17: 44956 | C17: 44927 | E17: Monthly Tax Accrual | F17: =-1477.35-1796.9-257.85-210.44 -> -3742.54
B18: 44985 | C18: 44958 | E18: Monthly Tax Accrual | F18: =-1477.35-1796.9-257.85-210.44 -> -3742.54
B19: 45015 | C19: 44986 | E19: Monthly Tax Accrual | F19: =-1477.35-1796.9-257.85-210.44 -> -3742.54
B20: 45046 | C20: 45017 | E20: Monthly Tax Accrual | F20: =-1477.35-1796.9-257.85-210.44 -> -3742.54
B21: 45076 | C21: 45047 | E21: Monthly Tax Accrual | F21: =-1477.35-1796.9-257.85-210.44 -> -3742.54
B22: 45107 | C22: 45078 | E22: Monthly Tax Accrual | F22: =-1477.35-1796.9-257.85-210.44 -> -3742.54
B23: 45137 | C23: 45108 | E23: Monthly Tax Accrual | F23: =-1477.35-1796.9-257.85-210.44 -> -3742.54
B24: 45168 | C24: 45139 | E24: Monthly Tax Accrual | F24: =-1477.35-1796.9-257.85-210.44 -> -3742.54
B25: 45199 | C25: 45170 | E25: Monthly Tax Accrual | F25: =-1477.35-1796.9-257.85-210.44 -> -3742.54
B26: 45229 | C26: 45200 | E26: Monthly Tax Accrual | F26: =-1477.35-1796.9-257.85-210.44 -> -3742.54
B27: 45260 | C27: 45231 | E27: Monthly Tax Accrual | F27: =-1477.35-1796.9-257.85-210.44 -> -3742.54
B28: 45290 | C28: 45261 | E28: Monthly Tax Accrual | F28: =-1477.35-1796.9-257.85-210.44 -> -3742.54
B29: 45422 | C29: =B29 -> 45422 | E29: Tax Payment | F29: =1661.16+2123.95+28120.65+15432.3 -> 47338.06 | H29: 2023 1st Installment Payment of Real Property Tax with PIN 45-16-05-487-002.000-042
E30: Tax Payment
E31: (Over)/Under Accrual | G31: =SUM(F17:F30) -> 2427.58
B33: 45321 | C33: 45292 | E33: Monthly Tax Accrual | F33: -8033.67
B34: 45351 | C34: 45323 | E34: Monthly Tax Accrual | F34: -8033.67
B35: 45381 | C35: 45352 | E35: Monthly Tax Accrual | F35: -8033.67
B36: 45412 | C36: 45383 | E36: Monthly Tax Accrual | F36: -8033.67
B37: 45442 | C37: 45413 | E37: Monthly Tax Accrual | F37: -8033.67
B38: 45473 | C38: 45444 | E38: Monthly Tax Accrual | F38: -8033.67
B39: 45503 | C39: 45474 | E39: Monthly Tax Accrual | F39: -8033.67
B40: 45534 | C40: 45505 | E40: Monthly Tax Accrual | F40: -8033.67
B41: 45565 | C41: 45536 | E41: Monthly Tax Accrual | F41: -8033.67
B42: 45595 | C42: 45566 | E42: Monthly Tax Accrual | F42: -8033.67
B43: 45626 | C43: =B43 -> 45626 | E43: Monthly Tax Accrual | F43: -8033.67
B44: 45657 | C44: =B44 -> 45657 | E44: Monthly Tax Accrual | F44: -8033.67
B45: 45593 | C45: =B45 -> 45593 | E45: Tax Payment | F45: 46258.06 | H45: RE tax payment from escrow
...

Sheet Sales Tax Collected
A1: =Cover!A1 -> SS of Crown Point West LLC (cpwest)
A2: =Cover!B2 -> 45930
A3: 2310-0000 Sales Tax Collected
E5: Account Balance | G5: =-INDEX('Yardi Report'!A:E,MATCH(LEFT(A3,9),'Yardi Report'!A:A,0),3) -> -302.44 | H5: =IF(G35=0,"","Out of Balance") -> Out of Balance
B7: Date | C7: Period | E7: G/L Description | G7: Amount | H7: Notes
C9: 45231 | E9: 11.2023 cc receipts | G9: =-1.4-0.49-1.76-1.4-1.4-1.4 -> -7.85
C10: 45261
C11: 45292
C12: 45323 | E12: 02.2024 cc receipts | G12: =-1.19-1.8 -> -2.99
C13: 45352 | E13: 03.2024 cc receipts | G13: =-1.8-0.31-0.52-1.8-1.8 -> -6.23
C14: 45383 | E14: 04.2024 cc receipts | G14: =-1.8-1.8-1.4-1.8-1.8-1.8-1.8-3.6-1.8-1.8-1.8-1.8-1.8 -> -24.8
C15: 45436 | E15: 05.2024 cc receipts | G15: =-1.8-1.8-3.6-1.8-1.8-1.8-4.3-3.6-1.8-1.8-3.2 -> -27.3
C16: 45467 | E16: 06.2024 cc receipts | G16: =-1.4-1.4-1.8-1.8-1.4-1.8-0.9-1.8-1.8-1.8-1.8-1.8-1.8 -> -21.3
C17: 45497 | E17: 07.2024 cc receipts | G17: =-1.8-1.8-0.9-1.8-1.4-1.8-3.6-0.9-1.8 -> -15.8
C18: 45528 | E18: 08.2024 cc receipts | G18: =-0.9-1.8-1.8-1.8-0.73-1.8-3.6 -> -12.43
C19: 45559 | E19: 09.2024 cc receipts | G19: =-1.4-1.8-5.4-1.8-1.49-0.9-1.8-2.7 -> -17.29
C20: 45589 | E20: 10.2024 cc receipts | G20: =-1.8-1.8-1.8-1.8-1.4-1.8-1.8 -> -12.2
C21: 45597 | E21: 11.2024 cc receipts | G21: =-3.6-1.8-1.8-1.8-1.8-1.8 -> -12.6
C22: 45657 | E22: 12.2024 cc receipts | G22: =-1.8-5.4-1.8-1.8-1.8-1.8 -> -14.4
C24: 45658 | E24: 01.2025 cc receipts | G24: -21.45
C25: 45716 | E25: 02.2025 cc receipts | G25: =-1.8-1.4-1.8-1.8 -> -6.8
C26: 45747 | E26: 03.2025 cc receipts | G26: =-1.8*4 -> -7.2
C27: 45748 | E27: 04.2025 cc receipts | G27: =-226.84+210.64 -> -16.2
C28: 45778 | E28: 05.2025 cc receipts | G28: -14.4
C29: 45809 | E29: 06.2025 cc receipts | G29: -19.8
C30: 45839 | E30: 07.2025 cc receipts | G30: -18
C31: 45870 | E31: 08.2025 cc receipts | G31: -7.2
C32: 45901 | E32: 09.2025 cc receipts | G32: -1.8
E35: Variance | G35: =ROUND(G5-SUM(G9:G34),2) -> -14.4 | H35: =IF(G35=0,"","Out of Balance") -> Out of Balance

Sheet Interest Accrual
A1: =Cover!A1 -> SS of Crown Point West LLC (cpwest)
A2: =Cover!B2 -> 45930
A3: 2609-0000 Interest Accrual
E5: Account Balance | G5: =-INDEX('Yardi Report'!A:E,MATCH(LEFT(A3,9),'Yardi Report'!A:A,0),3) -> -23796.06 | H5: =IF(G23=0,"","Out of Balance")
B7: Date | C7: Period | E7: G/L Description | G7: Amount | H7: Notes
B9: 45016 | C9: 44986 | E9: 31 days interest due on 4/2 payment | G9: -23796.06
E23: Variance | G23: =ROUND(G5-SUM(G9:G22),2) -> 0 | H23: =IF(G23=0,"","Out of Balance")

Sheet Expense Accrual
A1: =Cover!A1 -> SS of Crown Point West LLC (cpwest)
A2: =Cover!B2 -> 45930
A3: 2640-0998 Expense Accrual
E5: Account Balance | G5: =-INDEX('Yardi Report'!A:E,MATCH(LEFT(A3,9),'Yardi Report'!A:A,0),3) -> 4029.21 | H5: =IF(G165=0,"","Out of Balance") -> Out of Balance
B7: Date | E7: G/L Description | G7: Amount | H7: Notes
B9: 44957 | C9: 44927 | E9: EOM Expense Accrual - Sparefoot | G9: -221.1 | H9: Advertising
B10: 44985 | C10: 44958 | E10: Sparefoot accrual | G10: -163.35 | H10: Advertising
B12: 44895 | C12: 44866 | E12: Utility accruals for November - invoices not yet received | G12: -99 | H12: Answering Services
B14: 44987 | C14: 44986 | E14: Payment for NipsCo | G14: 8304.68 | H14: Chase Bank
B15: 45181 | C15: 45170 | E15: payment for Nipsco bills acct 3942190091 | G15: 186.64 | H15: Chase Bank
B16: 45181 | C16: 45170 | E16: payment for Nipsco bills acct 5147090005 | G16: 2756.57 | H16: Chase Bank
B17: 45216 | C17: 45200 | E17: Acct#5147090005 09/19/2023 to 10/17/2023 - cpwest | G17: 1140.65 | H17: Chase Bank
B18: 45226 | C18: 45200 | E18: NipsCo charge to be expensed | G18: 600.81 | H18: Chase Bank
B19: 45230 | C19: 45200 | E19: Nipsco payment to sellers old account after purchase | G19: 6038.3 | H19: Chase Bank
B20: 45473 | C20: 45444 | E20: Move P-77849 balance to Correct month | G20: 134.56 | H20: Chase Bank
B22: 45412 | C22: 45383 | E22: Storeease - not yet invoiced | G22: -150 | H22: Communication Center
B24: 44895 | C24: 44866 | E24: Utility accruals for November - invoices not yet received | G24: -170 | H24: Electricity
... B68: 45217 | C68: 45200 | E68: Review and correspondence with Att. Kutanovski and Bouwer. Agreed order 09/2023 services - CPWEST | G68: 174 | H68: Professional Consulting
B70: 45657 | C70: =B70 -> 45657 | E70: Sitelink November Accrual | G70: -330.76 | H70: Software
B72: 44926 | C72: 44896 | E72: Utility accruals for December - invoices not yet received | G72: -70 | H72: Telephone Services
B73: 45046 | C73: 45017 | E73: 04.2023 AT&T accrual | G73: -128.98 | H73: Telephone Services
B74: 45077 | C74: 45047 | E74: AT&T accrual | G74: -118.01 | H74: Telephone Services
B75: 45107 | C75: 45078 | E75: AT&T accrual | G75: -118 | H75: Telephone Services
B76: 45138 | C76: 45108 | E76: Accrue for telephone | G76: -118 | H76: Telephone Services
B77: 45198 | C77: 45170 | E77: Accrue for invoice not yet received | G77: -118 | H77: Telephone Services
B78: 45230 | C78: 45200 | E78: AT&T accrual | G78: -118 | H78: Telephone Services
B79: 45260 | C79: 45231 | E79: AT&T accrual | G79: -118 | H79: Telephone Services
B80: 45291 | C80: 45261 | E80: AT&T accrual | G80: -118 | H80: Telephone Services
B82: 45107 | C82: 45078 | E82: Total Disposal accrual, no invoice | G82: -95 | H82: Trash Disposal
B83: 45138 | C83: 45108 | E83: July EOM accruals | G83: -95 | H83: Trash Disposal
B84: 45230 | C84: 45231 | E84: Total Disposal payment on accrued expenses | G84: 96.76 | H84: Trash Disposal
... B92: 45138 | C92: 45108 | E92: July EOM accruals | G92: -66.11 | H92: Water and Sewer
B93: 45291 | C93: 45261 | E93: Water & Sewer accrual | G93: =-66.11+13.2+13.2+14.4-12-12 -> -49.31 | H93: Water and Sewer
B95: 45504 | C95: 45474 | E95: Capital One 06/2024 - SS Crown Point West | G95: 1703.58
B96: 45596 | C96: 45566 | E96: Capital One 10/2024 - SS Crown Point West | G96: -622.17
B97: 45609 | C97: =B97 -> 45609 | E97: 10.2024 CapOne | G97: 500
B101: 45747 | C101: =B101 -> 45747 | E101: 032025BankFeesSSofCPWest | G101: -268.49 | H101: Bank Charges Expense
B103: 45716 | C103: =B103 -> 45716 | E103: 02.2025 Orkin Accrual | G103: -132 | H103: Extermination
B104: 45716 | C104: =B104 -> 45716 | E104: Orkin _ Bill received | G104: 132 | H104: Extermination
B106: 45930 | C106: 45901 | E106: Sitelink 09/2025 | G106: -350.61 | H106: Software
...

Sheet Sheet2
C4: 45626 | E4: Electric accrual per UW model | H4: -318
C5: 45626 | E5: Gas accrual per UW model | H5: -847
C6: 45626 | E6: Water & Sewer accrual per UW model | H6: -212
C7: 45657 | E7: Accruals until invoicing is received Elec | H7: -325
C8: 45657 | E8: Accruals until invoicing is received Gas | H8: -850
C9: 45657 | E9: Accruals until invoicing is received Water/Sewer | H9: -215
C10: 45322 | E10: Duke energy payment to offset accruals | H10: 790
C11: 45382 | E11: Month end accrual_Gas | H11: -1694
C12: 45382 | E12: Month end accrual_Water and Sewer | H12: -645
C13: 45412 | E13: Gas, Water and Sewer Accruals 042024 | H13: -1062
C14: 45443 | E14: Gas, Water and Sewer Accruals 052024 | H14: -1062
C15: 45473 | E15: Gas, Water and Sewer Accruals 062024 | H15: -1062
... C21: 45535 | E21: Gas / Water and Sewer Accruals 082024 | H21: -1062
H23: =SUM(H4:H21) -> -11624.99 | L23: 7461.68
H25: 11727.63
H27: =+H25+H23 -> 102.64
H29: -330.98
H30: 228.34
H32: =+H30+H29+H27 -> -5.968559e-13

Sheet Yardi Report
A1: SS of Crown Point West LLC (cpwest)
A2: Balance Sheet (With Period Change)
A3: Period = Jan 2025-Oct 2025
A4: Book = Accrual
C5: Balance | D5: Beginning | E5: Net
C6: Current Period | D6: Balance | E6: Change
A7: 1000-0000 | B7: ASSETS
A9: 1100-0000 | B9: CASH
A10: 1110-4947 | B10: Crown Point West Chase | C10: 10156.64 | D10: 10377.32 | E10: -220.68
A11: 1110-4957 | B11: Crown Point West Centier Operating | C11: -23118.74 | D11: -16724.16 | E11: -6394.58
A12: 1190-0000 | B12: TOTAL CASH | C12: -12962.1 | D12: -6346.84 | E12: -6615.26
A14: 1200-0000 | B14: RESTRICTED CASH
A15: 1200-0003 | B15: Escrow Reserve | C15: 97318.38 | D15: 8846.78 | E15: 88471.6
A16: 1200-0005 | B16: Utility Security Deposits | C16: 8420 | D16: 8420 | E16: 0
A17: 1200-0006 | B17: Crown Point West Centier | C17: 250000 | D17: 250000 | E17: 0
A18: 1200-0008 | B18: SS of Crown Point West Held | C18: 155108 | D18: 210998 | E18: -55890
A19: 1250-0000 | B19: TOTAL RESTRICTED CASH | C19: 510846.38 | D19: 478264.78 | E19: 32581.6
A21: 1300-0000 | B21: Accounts Receivable | C21: 85567.45 | D21: 51212.33 | E21: 34355.12
A23: 1350-0000 | B23: Pre-Paid Expenses
A24: 1350-0001 | B24: Pre-Paid Insurance | C24: 460.54 | D24: 11820 | E24: -11359.46
A25: 1350-9999 | B25: Total Pre-Paid Expenses | C25: 460.54 | D25: 11820 | E25: -11359.46
A27: 1400-0000 | B27: PROPERTY
A28: 1410-0000 | B28: Land | C28: 568379.08 | D28: 568379.08 | E28: 0
A29: 1500-0000 | B29: Building | C29: 7558517 | D29: 7558517 | E29: 0
A30: 1500-0001 | B30: 5 Year Property | C30: 11143.25 | D30: 11143.25 | E30: 0
A31: 1500-0010 | B31: Building Improvements | C31: 1650650 | D31: 1650650 | E31: 0
A32: 1500-0040 | B32: Loan Fees A | C32: 97738.25 | D32: 97738.25 | E32: 0
A33: 1500-0050 | B33: AD Building | C33: -408726 | D33: -408726 | E33: 0
A34: 1500-0051 | B34: A/D 5 Year Property | C34: 4458 | D34: 4458 | E34: 0
A35: 1500-0060 | B35: A/D Building Improvements | C35: -27511 | D35: -27511 | E35: 0
A36: 1500-0085 | B36: A/A Loan Fees - A | C36: -35838 | D36: -35838 | E36: 0
A38: 1600-0000 | B38: CONSTRUCTION IN PROGRESS
A39: 1600-0035 | B39: Architect | C39: 1200 | D39: 0 | E39: 1200
A40: 1600-1000 | B40: Draws
A41: 1600-9999 | B41: TOTAL CONSTRUCTION IN PROGRESS | C41: 1200 | D41: 0 | E41: 1200
A42: 1890-0000 | B42: TOTAL PROPERTY | C42: 9411094.5 | D42: 9409894.5 | E42: 1200
A44: 1990-0000 | B44: TOTAL ASSETS | C44: 9995006.8 | D44: 9944844.8 | E44: 50162
A46: 2000-0000 | B46: LIABILITIES AND CAPITAL
A48: 2100-0000 | B48: LIABILITIES
A49: 2110-0000 | B49: Note 1 Principal | C49: 5905995.8 | D49: 6063747.1 | E49: -157751.26
...

Sheet Chart of Accounts
A1: Chart of Accounts
A5: Account | B5: Account Name | C5: Normal | D5: Acct | E5: Rpt | G5: Line | H5: Offset | I5: Hold-For | J5: Accrual | K5: Total | L5: Flags
C6: Balance | D6: Type | E6: Type | F6: Margin | G6: Adv. | H6: Account | I6: Account | J6: Account | K6: Account
A7: 1000-0000 | B7: ASSETS | C7: Debit | D7: Head | E7: Bal | F7: 1 | G7: 1
A8: 1100-0000 | B8: CASH | C8: Debit | D8: Head | E8: Bal | F8: 1 | G8: 2
A9: 1100-0001 | B9: Cash Reserve | C9: Debit | D9: Reg | E9: Bal | F9: 1 | G9: 1 | L9: Cash
A10: 1100-0500 | B10: do not use | C10: Debit | D10: Reg | E10: Bal | F10: 1 | G10: 1 | K10: 1190-0000 | L10: Cash
A11: 1110-0000 | B11: BMO Harris | C11: Debit | D11: Reg | E11: Bal | F11: 1 | G11: 1 | K11: 1190-0000 | L11: Cash
A12: 1110-0001 | B12: BMO Harris Reserves 3839 | C12: Debit | D12: Reg | E12: Bal | F12: 1 | G12: 1 | K12: 1190-0000 | L12: Cash
A13: 1110-0002 | B13: Associated Bank - Operating | C13: Debit | D13: Reg | E13: Bal | F13: 1 | G13: 1 | K13: 1190-0000 | L13: Cash
A14: 1110-0003 | B14: 8211 Kilpatrick BB Checking | C14: Debit | D14: Reg | E14: Bal | F14: 1 | G14: 1 | K14: 1190-0000 | L14: Cash
A15: 1110-0004 | B15: 8211 Kilpatrick BB Savings | C15: Debit | D15: Reg | E15: Bal | F15: 1 | G15: 1 | K15: 1190-0000 | L15: Cash
A16: 1110-0005 | B16: 3830 Ashland Amal Checking | C16: Debit | D16: Reg | E16: Bal | F16: 1 | G16: 1 | K16: 1190-0000 | L16: Cash
A17: 1110-0006 | B17: 3830 Ashland Amal Savings | C17: Debit | D17: Reg | E17: Bal | F17: 1 | G17: 1 | K17: 1190-0000 | L17: Cash
A18: 1110-0010 | B18: Belmont Bank & Trust WC | C18: Debit | D18: Reg | E18: Bal | F18: 1 | G18: 1 | K18: 1190-0000 | L18: Cash
A19: 1110-0020 | B19: Belmont Bank and Trust Ruby Street | C19: Debit | D19: Reg | E19: Bal | F19: 1 | G19: 1 | K19: 1190-0000 | L19: Cash
A20: 1110-0030 | B20: Belmont Bank and Trust Indian Creek | C20: Debit | D20: Reg | E20: Bal | F20: 1 | G20: 1 | K20: 1190-0000 | L20: Cash
A21: 1110-0040 | B21: Belmont Bank and Trust Sherman Place | C21: Debit | D21: Reg | E21: Bal | F21: 1 | G21: 1 | K21: 1190-0000 | L21: Cash
... A135: 1110-4944 | B135: Palm Bay Key Bank | C135: Debit | D135: Reg | E135: Bal | F135: 1 | G135: 1 | K135: 1190-0000 | L135: Cash
A136: 1110-4945 | B136: Silver Springs Equitable Bank | C136: Debit | D136: Reg | E136: Inc | F136: 1 | G136: 1 | L136: ExclReg, Exclude
A137: 1110-4946 | B137: Silver Springs Equitable Bank | C137: Debit | D137: Reg | E137: Bal | F137: 1 | G137: 1 | K137: 1190-0000 | L137: Cash
A138: 1110-4947 | B138: Crown Point West Chase | C138: Debit | D138: Reg | E138: Bal | F138: 1 | G138: 1 | K138: 1190-0000 | L138: Cash
A139: 1110-4948 | B139: Merrillville South Chase | C139: Debit | D139: Reg | E139: Bal | F139: 1 | G139: 1 | K139: 1190-0000 | L139: Cash
A140: 1110-4949 | B140: SS of Palm Bay Busey Bank | C140: Debit | D140: Reg | E140: Bal | F140: 1 | G140: 1 | K140: 1190-0000 | L140: Cash
A141: 1110-4950 | B141: SS of Port Washington Chase | C141: Debit | D141: Reg | E141: Bal | F141: 1 | G141: 1 | K141: 1190-0000 | L141: Cash
A142: 1110-4951 | B142: MSS Chase | C142: Debit | D142: Reg | E142: Bal | F142: 1 | G142: 1 | K142: 1190-0000 | L142: Cash
A143: 1110-4952 | B143: CPSS Chase | C143: Debit | D143: Reg | E143: Bal | F143: 1 | G143: 1 | K143: 1190-0000 | L143: Cash
A144: 1110-4953 | B144: NFSS Chase | C144: Debit | D144: Reg | E144: Bal | F144: 1 | G144: 1 | K144: 1190-0000 | L144: Cash
A145: 1110-4954 | B145: SSWwd Chase | C145: Debit | D145: Reg | E145: Bal | F145: 1 | G145: 1 | K145: 1190-0000 | L145: Cash
A146: 1110-4955 | B146: SSWwd Busey | C146: Debit | D146: Reg | E146: Bal | F146: 1 | G146: 1 | K146: 1190-0000 | L146: Cash
A147: 1110-4957 | B147: Crown Point West Centier Operating | C147: Debit | D147: Reg | E147: Bal | F147: 1 | G147: 1 | K147: 1190-0000 | L147: Cash
A148: 1110-4958 | B148: Rockledge Centier Money Market | C148: Debit | D148: Reg | E148: Bal | F148: 1 | G148: 1 | K148: 1190-0000 | L148: Cash
... A188: 1140-0000 | B188: Association Reserve Account | C188: Debit | D188: Reg | E188: Bal | F188: 1 | G188: 1 | K188: 1190-0000 | L188: Cash
A189: 1140-8521 | B189: 21.8521 Association Reserve Account | C189: Debit | D189: Reg | E189: Inc | F189: 0 | G189: 1 | L189: Cash
A190: 1150-0000 | B190: Rent to RDG | C190: Debit | D190: Reg | E190: Bal | F190: 1 | G190: 1 | L190: Cash
A191: 1160-0000 | B191: Deposits to RDG | C191: Debit | D191: Reg | E191: Bal | F191: 1 | G191: 1 | L191: Cash
A192: 1170-0000 | B192: Transfers to RDG | C192: Debit | D192: Reg | E192: Bal | F192: 1 | G192: 1 | L192: Cash
A193: 1180-0000 | B193: Funds To From Martin & Marbry | C193: Debit | D193: Reg | E193: Bal | F193: 1 | G193: 1 | K193: 2990-0000 | L193: Cash, ExclReg
A194: 1190-0000 | B194: TOTAL CASH | C194: Debit | D194: Tot | E194: Bal | F194: 2 | G194: 1 | K194: 1990-0000
A195: 1190-0020 | B195: American Eagle Bank | C195: Debit | D195: Reg | E195: Bal | F195: 1 | G195: 1 | K195: 1190-0000 | L195: Cash
...

Sheet Account Table
A1: =IF(ISNA(INDEX('Yardi Report'!$A:$E,MATCH('Chart of Accounts'!$A7,'Yardi Report'!$A:$A,0),1)),"",INDEX('Yardi Report'!$A:$E,MATCH('Chart of Accounts'!$A7,'Yardi Report'!$A:$A,0),1)) -> 1000-0000 | B1: =IF(ISNA(INDEX('Yardi Report'!$A:$E,MATCH('Chart of Accounts'!$A7,'Yardi Report'!$A:$A,0),2)),"",INDEX('Yardi Report'!$A:$E,MATCH('Chart of Accounts'!$A7,'Yardi Report'!$A:$A,0),2)) -> ASSETS | C1: =IF(A1="","",1) -> 1 | E1: =A1&" "&B1 -> 1000-0000 ASSETS | G1: 1 | H1: =IF(ISNA(INDEX(C1:E500,MATCH(G1,C1:C500,0),3)),"",INDEX(C1:E500,MATCH(G1,C1:C500,0),3)) -> 1000-0000 ASSETS
A2: =IF(ISNA(INDEX('Yardi Report'!$A:$E,MATCH('Chart of Accounts'!$A8,'Yardi Report'!$A:$A,0),1)),"",INDEX('Yardi Report'!$A:$E,MATCH('Chart of Accounts'!$A8,'Yardi Report'!$A:$A,0),1)) -> 1100-0000 | B2: =IF(ISNA(INDEX('Yardi Report'!$A:$E,MATCH('Chart of Accounts'!$A8,'Yardi Report'!$A:$A,0),2)),"",INDEX('Yardi Report'!$A:$E,MATCH('Chart of Accounts'!$A8,'Yardi Report'!$A:$A,0),2)) -> CASH | C2: =IF(A2="","",C1+1) -> 2 | E2: =A2&" "&B2 -> 1100-0000 CASH | G2: =+G1+1 -> 2 | H2: =IF(ISNA(INDEX(C2:E501,MATCH(G2,C2:C501,0),3)),"",INDEX(C2:E501,MATCH(G2,C2:C501,0),3)) -> 1100-0000 CASH
A3: =IF(ISNA(INDEX('Yardi Report'!$A:$E,MATCH('Chart of Accounts'!$A9,'Yardi Report'!$A:$A,0),1)),"",INDEX('Yardi Report'!$A:$E,MATCH('Chart of Accounts'!$A9,'Yardi Report'!$A:$A,0),1)) | B3: =IF(ISNA(INDEX('Yardi Report'!$A:$E,MATCH('Chart of Accounts'!$A9,'Yardi Report'!$A:$A,0),2)),"",INDEX('Yardi Report'!$A:$E,MATCH('Chart of Accounts'!$A9,'Yardi Report'!$A:$A,0),2)) | C3: =IF(A3="","",MAX($C$1:C2)+1) | E3: =A3&" "&B3 | G3: =+G2+1 -> 3 | H3: =IF(ISNA(INDEX(C3:E502,MATCH(G3,C3:C502,0),3)),"",INDEX(C3:E502,MATCH(G3,C3:C502,0),3)) -> 1110-4947 Crown Point West Chase
A4: =IF(ISNA(INDEX('Yardi Report'!$A:$E,MATCH('Chart of Accounts'!$A10,'Yardi Report'!$A:$A,0),1)),"",INDEX('Yardi Report'!$A:$E,MATCH('Chart of Accounts'!$A10,'Yardi Report'!$A:$A,0),1)) | B4: =IF(ISNA(INDEX('Yardi Report'!$A:$E,MATCH('Chart of Accounts'!$A10,'Yardi Report'!$A:$A,0),2)),"",INDEX('Yardi Report'!$A:$E,MATCH('Chart of Accounts'!$A10,'Yardi Report'!$A:$A,0),2)) | C4: =IF(A4="","",MAX($C$1:C3)+1) | E4: =A4&" "&B4 | G4: =+G3+1 -> 4 | H4: =IF(ISNA(INDEX(C4:E503,MATCH(G4,C4:C503,0),3)),"",INDEX(C4:E503,MATCH(G4,C4:C503,0),3)) -> 1110-4957 Crown Point West Centier Operating
A5: =IF(ISNA(INDEX('Yardi Report'!$A:$E,MATCH('Chart of Accounts'!$A11,'Yardi Report'!$A:$A,0),1)),"",INDEX('Yardi Report'!$A:$E,MATCH('Chart of Accounts'!$A11,'Yardi Report'!$A:$A,0),1)) | B5: =IF(ISNA(INDEX('Yardi Report'!$A:$E,MATCH('Chart of Accounts'!$A11,'Yardi Report'!$A:$A,0),2)),"",INDEX('Yardi Report'!$A:$E,MATCH('Chart of Accounts'!$A11,'Yardi Report'!$A:$A,0),2)) | C5: =IF(A5="","",MAX($C$1:C4)+1) | E5: =A5&" "&B5 | G5: =+G4+1 -> 5 | H5: =IF(ISNA(INDEX(C5:E504,MATCH(G5,C5:C504,0),3)),"",INDEX(C5:E504,MATCH(G5,C5:C504,0),3)) -> 1190-0000 TOTAL CASH
A6: =IF(ISNA(INDEX('Yardi Report'!$A:$E,MATCH('Chart of Accounts'!$A12,'Yardi Report'!$A:$A,0),1)),"",INDEX('Yardi Report'!$A:$E,MATCH('Chart of Accounts'!$A12,'Yardi Report'!$A:$A,0),1)) | B6: =IF(ISNA(INDEX('Yardi Report'!$A:$E,MATCH('Chart of Accounts'!$A12,'Yardi Report'!$A:$A,0),2)),"",INDEX('Yardi Report'!$A:$E,MATCH('Chart of Accounts'!$A12,'Yardi Report'!$A:$A,0),2)) | C6: =IF(A6="","",MAX($C$1:C5)+1) | E6: =A6&" "&B6 | G6: =+G5+1 -> 6 | H6: =IF(ISNA(INDEX(C6:E505,MATCH(G6,C6:C505,0),3)),"",INDEX(C6:E505,MATCH(G6,C6:C505,0),3)) -> 1200-0000 RESTRICTED CASH
A7: =IF(ISNA(INDEX('Yardi Report'!$A:$E,MATCH('Chart of Accounts'!$A13,'Yardi Report'!$A:$A,0),1)),"",INDEX('Yardi Report'!$A:$E,MATCH('Chart of Accounts'!$A13,'Yardi Report'!$A:$A,0),1)) | B7: =IF(ISNA(INDEX('Yardi Report'!$A:$E,MATCH('Chart of Accounts'!$A13,'Yardi Report'!$A:$A,0),2)),"",INDEX('Yardi Report'!$A:$E,MATCH('Chart of Accounts'!$A13,'Yardi Report'!$A:$A,0),2)) | C7: =IF(A7="","",MAX($C$1:C6)+1) | E7: =A7&" "&B7 | G7: =+G6+1 -> 7 | H7: =IF(ISNA(INDEX(C7:E506,MATCH(G7,C7:C506,0),3)),"",INDEX(C7:E506,MATCH(G7,C7:C506,0),3)) -> 1200-0003 Escrow Reserve
A8: =IF(ISNA(INDEX('Yardi Report'!$A:$E,MATCH('Chart of Accounts'!$A14,'Yardi Report'!$A:$A,0),1)),"",INDEX('Yardi Report'!$A:$E,MATCH('Chart of Accounts'!$A14,'Yardi Report'!$A:$A,0),1)) | B8: =IF(ISNA(INDEX('Yardi Report'!$A:$E,MATCH('Chart of Accounts'!$A14,'Yardi Report'!$A:$A,0),2)),"",INDEX('Yardi Report'!$A:$E,MATCH('Chart of Accounts'!$A14,'Yardi Report'!$A:$A,0),2)) | C8: =IF(A8="","",MAX($C$1:C7)+1) | E8: =A8&" "&B8 | G8: =+G7+1 -> 8 | H8: =IF(ISNA(INDEX(C8:E507,MATCH(G8,C8:C507,0),3)),"",INDEX(C8:E507,MATCH(G8,C8:C507,0),3)) -> 1200-0005 Utility Security Deposits
A9: =IF(ISNA(INDEX('Yardi Report'!$A:$E,MATCH('Chart of Accounts'!$A15,'Yardi Report'!$A:$A,0),1)),"",INDEX('Yardi Report'!$A:$E,MATCH('Chart of Accounts'!$A15,'Yardi Report'!$A:$A,0),1)) | B9: =IF(ISNA(INDEX('Yardi Report'!$A:$E,MATCH('Chart of Accounts'!$A15,'Yardi Report'!$A:$A,0),2)),"",INDEX('Yardi Report'!$A:$E,MATCH('Chart of Accounts'!$A15,'Yardi Report'!$A:$A,0),2)) | C9: =IF(A9="","",MAX($C$1:C8)+1) | E9: =A9&" "&B9 | G9: =+G8+1 -> 9 | H9: =IF(ISNA(INDEX(C9:E508,MATCH(G9,C9:C508,0),3)),"",INDEX(C9:E508,MATCH(G9,C9:C508,0),3)) -> 1200-0006 Crown Point West Centier
A10: =IF(ISNA(INDEX('Yardi Report'!$A:$E,MATCH('Chart of Accounts'!$A16,'Yardi Report'!$A:$A,0),1)),"",INDEX('Yardi Report'!$A:$E,MATCH('Chart of Accounts'!$A16,'Yardi Report'!$A:$A,0),1)) | B10: =IF(ISNA(INDEX('Yardi Report'!$A:$E,MATCH('Chart of Accounts'!$A16,'Yardi Report'!$A:$A,0),2)),"",INDEX('Yardi Report'!$A:$E,MATCH('Chart of Accounts'!$A16,'Yardi Report'!$A:$A,0),2)) | C10: =IF(A10="","",MAX($C$1:C9)+1) | E10: =A10&" "&B10 | G10: =+G9+1 -> 10 | H10: =IF(ISNA(INDEX(C10:E509,MATCH(G10,C10:C509,0),3)),"",INDEX(C10:E509,MATCH(G10,C10:C509,0),3)) -> 1200-0008 SS of Crown Point West Held
A11: =IF(ISNA(INDEX('Yardi Report'!$A:$E,MATCH('Chart of Accounts'!$A17,'Yardi Report'!$A:$A,0),1)),"",INDEX('Yardi Report'!$A:$E,MATCH('Chart of Accounts'!$A17,'Yardi Report'!$A:$A,0),1)) | B11: =IF(ISNA(INDEX('Yardi Report'!$A:$E,MATCH('Chart of Accounts'!$A17,'Yardi Report'!$A:$A,0),2)),"",INDEX('Yardi Report'!$A:$E,MATCH('Chart of Accounts'!$A17,'Yardi Report'!$A:$A,0),2)) | C11: =IF(A11="","",MAX($C$1:C10)+1) | E11: =A11&" "&B11 | G11: =+G10+1 -> 11 | H11: =IF(ISNA(INDEX(C11:E510,MATCH(G11,C11:C510,0),3)),"",INDEX(C11:E510,MATCH(G11,C11:C510,0),3)) -> 1250-0000 TOTAL RESTRICTED CASH
A12: =IF(ISNA(INDEX('Yardi Report'!$A:$E,MATCH('Chart of Accounts'!$A18,'Yardi Report'!$A:$A,0),1)),"",INDEX('Yardi Report'!$A:$E,MATCH('Chart of Accounts'!$A18,'Yardi Report'!$A:$A,0),1)) | B12: =IF(ISNA(INDEX('Yardi Report'!$A:$E,MATCH('Chart of Accounts'!$A18,'Yardi Report'!$A:$A,0),2)),"",INDEX('Yardi Report'!$A:$E,MATCH('Chart of Accounts'!$A18,'Yardi Report'!$A:$A,0),2)) | C12: =IF(A12="","",MAX($C$1:C11)+1) | E12: =A12&" "&B12 | G12: =+G11+1 -> 12 | H12: =IF(ISNA(INDEX(C12:E511,MATCH(G12,C12:C511,0),3)),"",INDEX(C12:E511,MATCH(G12,C12:C511,0),3)) -> 1300-0000 Accounts Receivable
A13: =IF(ISNA(INDEX('Yardi Report'!$A:$E,MATCH('Chart of Accounts'!$A19,'Yardi Report'!$A:$A,0),1)),"",INDEX('Yardi Report'!$A:$E,MATCH('Chart of Accounts'!$A19,'Yardi Report'!$A:$A,0),1)) | B13: =IF(ISNA(INDEX('Yardi Report'!$A:$E,MATCH('Chart of Accounts'!$A19,'Yardi Report'!$A:$A,0),2)),"",INDEX('Yardi Report'!$A:$E,MATCH('Chart of Accounts'!$A19,'Yardi Report'!$A:$A,0),2)) | C13: =IF(A13="","",MAX($C$1:C12)+1) | E13: =A13&" "&B13 | G13: =+G12+1 -> 13 | H13: =IF(ISNA(INDEX(C13:E512,MATCH(G13,C13:C512,0),3)),"",INDEX(C13:E512,MATCH(G13,C13:C512,0),3)) -> 1350-0000 Pre-Paid Expenses
A14: =IF(ISNA(INDEX('Yardi Report'!$A:$E,MATCH('Chart of Accounts'!$A20,'Yardi Report'!$A:$A,0),1)),"",INDEX('Yardi Report'!$A:$E,MATCH('Chart of Accounts'!$A20,'Yardi Report'!$A:$A,0),1)) | B14: =IF(ISNA(INDEX('Yardi Report'!$A:$E,MATCH('Chart of Accounts'!$A20,'Yardi Report'!$A:$A,0),2)),"",INDEX('Yardi Report'!$A:$E,MATCH('Chart of Accounts'!$A20,'Yardi Report'!$A:$A,0),2)) | C14: =IF(A14="","",MAX($C$1:C13)+1) | E14: =A14&" "&B14 | G14: =+G13+1 -> 14 | H14: =IF(ISNA(INDEX(C14:E513,MATCH(G14,C14:C513,0),3)),"",INDEX(C14:E513,MATCH(G14,C14:C513,0),3)) -> 1350-0001 Pre-Paid Insurance
... A100: =IF(ISNA(INDEX('Yardi Report'!$A:$E,MATCH('Chart of Accounts'!$A106,'Yardi Report'!$A:$A,0),1)),"",INDEX('Yardi Report'!$A:$E,MATCH('Chart of Accounts'!$A106,'Yardi Report'!$A:$A,0),1)) | B100: =IF(ISNA(INDEX('Yardi Report'!$A:$E,MATCH('Chart of Accounts'!$A106,'Yardi Report'!$A:$A,0),2)),"",INDEX('Yardi Report'!$A:$E,MATCH('Chart of Accounts'!$A106,'Yardi Report'!$A:$A,0),2)) | C100: =IF(A100="","",MAX($C$1:C99)+1) | E100: =A100&" "&B100 | G100: =+G99+1 -> 100 | H100: =IF(ISNA(INDEX(C100:E599,MATCH(G100,C100:C599,0),3)),"",INDEX(C100:E599,MATCH(G100,C100:C599,0),3))
A101: =IF(ISNA(INDEX('Yardi Report'!$A:$E,MATCH('Chart of Accounts'!$A107,'Yardi Report'!$A:$A,0),1)),"",INDEX('Yardi Report'!$A:$E,MATCH('Chart of Accounts'!$A107,'Yardi Report'!$A:$A,0),1)) | B101: =IF(ISNA(INDEX('Yardi Report'!$A:$E,MATCH('Chart of Accounts'!$A107,'Yardi Report'!$A:$A,0),2)),"",INDEX('Yardi Report'!$A:$E,MATCH('Chart of Accounts'!$A107,'Yardi Report'!$A:$A,0),2)) | C101: =IF(A101="","",MAX($C$1:C100)+1) | E101: =A101&" "&B101 | G101: =+G100+1 -> 101
A102: =IF(ISNA(INDEX('Yardi Report'!$A:$E,MATCH('Chart of Accounts'!$A108,'Yardi Report'!$A:$A,0),1)),"",INDEX('Yardi Report'!$A:$E,MATCH('Chart of Accounts'!$A108,'Yardi Report'!$A:$A,0),1)) | B102: =IF(ISNA(INDEX('Yardi Report'!$A:$E,MATCH('Chart of Accounts'!$A108,'Yardi Report'!$A:$A,0),2)),"",INDEX('Yardi Report'!$A:$E,MATCH('Chart of Accounts'!$A108,'Yardi Report'!$A:$A,0),2)) | C102: =IF(A102="","",MAX($C$1:C101)+1) | E102: =A102&" "&B102 | G102: =+G101+1 -> 102
A103: =IF(ISNA(INDEX('Yardi Report'!$A:$E,MATCH('Chart of Accounts'!$A109,'Yardi Report'!$A:$A,0),1)),"",INDEX('Yardi Report'!$A:$E,MATCH('Chart of Accounts'!$A109,'Yardi Report'!$A:$A,0),1)) | B103: =IF(ISNA(INDEX('Yardi Report'!$A:$E,MATCH('Chart of Accounts'!$A109,'Yardi Report'!$A:$A,0),2)),"",INDEX('Yardi Report'!$A:$E,MATCH('Chart of Accounts'!$A109,'Yardi Report'!$A:$A,0),2)) | C103: =IF(A103="","",MAX($C$1:C102)+1) | E103: =A103&" "&B103 | G103: =+G102+1 -> 103
A104: =IF(ISNA(INDEX('Yardi Report'!$A:$E,MATCH('Chart of Accounts'!$A110,'Yardi Report'!$A:$A,0),1)),"",INDEX('Yardi Report'!$A:$E,MATCH('Chart of Accounts'!$A110,'Yardi Report'!$A:$A,0),1)) | B104: =IF(ISNA(INDEX('Yardi Report'!$A:$E,MATCH('Chart of Accounts'!$A110,'Yardi Report'!$A:$A,0),2)),"",INDEX('Yardi Report'!$A:$E,MATCH('Chart of Accounts'!$A110,'Yardi Report'!$A:$A,0),2)) | C104: =IF(A104="","",MAX($C$1:C103)+1) | E104: =A104&" "&B104 | G104: =+G103+1 -> 104
A105: =IF(ISNA(INDEX('Yardi Report'!$A:$E,MATCH('Chart of Accounts'!$A111,'Yardi Report'!$A:$A,0),1)),"",INDEX('Yardi Report'!$A:$E,MATCH('Chart of Accounts'!$A111,'Yardi Report'!$A:$A,0),1)) | B105: =IF(ISNA(INDEX('Yardi Report'!$A:$E,MATCH('Chart of Accounts'!$A111,'Yardi Report'!$A:$A,0),2)),"",INDEX('Yardi Report'!$A:$E,MATCH('Chart of Accounts'!$A111,'Yardi Report'!$A:$A,0),2)) | C105: =IF(A105="","",MAX($C$1:C104)+1) | E105: =A105&" "&B105 | G105: =+G104+1 -> 105
A106: =IF(ISNA(INDEX('Yardi Report'!$A:$E,MATCH('Chart of Accounts'!$A112,'Yardi Report'!$A:$A,0),1)),"",INDEX('Yardi Report'!$A:$E,MATCH('Chart of Accounts'!$A112,'Yardi Report'!$A:$A,0),1)) | B106: =IF(ISNA(INDEX('Yardi Report'!$A:$E,MATCH('Chart of Accounts'!$A112,'Yardi Report'!$A:$A,0),2)),"",INDEX('Yardi Report'!$A:$E,MATCH('Chart of Accounts'!$A112,'Yardi Report'!$A:$A,0),2)) | C106: =IF(A106="","",MAX($C$1:C105)+1) | E106: =A106&" "&B106 | G106: =+G105+1 -> 106
A107: =IF(ISNA(INDEX('Yardi Report'!$A:$E,MATCH('Chart of Accounts'!$A113,'Yardi Report'!$A:$A,0),1)),"",INDEX('Yardi Report'!$A:$E,MATCH('Chart of Accounts'!$A113,'Yardi Report'!$A:$A,0),1)) | B107: =IF(ISNA(INDEX('Yardi Report'!$A:$E,MATCH('Chart of Accounts'!$A113,'Yardi Report'!$A:$A,0),2)),"",INDEX('Yardi Report'!$A:$E,MATCH('Chart of Accounts'!$A113,'Yardi Report'!$A:$A,0),2)) | C107: =IF(A107="","",MAX($C$1:C106)+1) | E107: =A107&" "&B107 | G107: =+G106+1 -> 107
A108: =IF(ISNA(INDEX('Yardi Report'!$A:$E,MATCH('Chart of Accounts'!$A114,'Yardi Report'!$A:$A,0),1)),"",INDEX('Yardi Report'!$A:$E,MATCH('Chart of Accounts'!$A114,'Yardi Report'!$A:$A,0),1)) | B108: =IF(ISNA(INDEX('Yardi Report'!$A:$E,MATCH('Chart of Accounts'!$A114,'Yardi Report'!$A:$A,0),2)),"",INDEX('Yardi Report'!$A:$E,MATCH('Chart of Accounts'!$A114,'Yardi Report'!$A:$A,0),2)) | C108: =IF(A108="","",MAX($C$1:C107)+1) | E108: =A108&" "&B108 | G108: =+G107+1 -> 108
A109: =IF(ISNA(INDEX('Yardi Report'!$A:$E,MATCH('Chart of Accounts'!$A115,'Yardi Report'!$A:$A,0),1)),"",INDEX('Yardi Report'!$A:$E,MATCH('Chart of Accounts'!$A115,'Yardi Report'!$A:$A,0),1)) | B109: =IF(ISNA(INDEX('Yardi Report'!$A:$E,MATCH('Chart of Accounts'!$A115,'Yardi Report'!$A:$A,0),2)),"",INDEX('Yardi Report'!$A:$E,MATCH('Chart of Accounts'!$A115,'Yardi Report'!$A:$A,0),2)) | C109: =IF(A109="","",MAX($C$1:C108)+1) | E109: =A109&" "&B109 | G109: =+G108+1 -> 109
A110: =IF(ISNA(INDEX('Yardi Report'!$A:$E,MATCH('Chart of Accounts'!$A116,'Yardi Report'!$A:$A,0),1)),"",INDEX('Yardi Report'!$A:$E,MATCH('Chart of Accounts'!$A116,'Yardi Report'!$A:$A,0),1)) | B110: =IF(ISNA(INDEX('Yardi Report'!$A:$E,MATCH('Chart of Accounts'!$A116,'Yardi Report'!$A:$A,0),2)),"",INDEX('Yardi Report'!$A:$E,MATCH('Chart of Accounts'!$A116,'Yardi Report'!$A:$A,0),2)) | C110: =IF(A110="","",MAX($C$1:C109)+1) | E110: =A110&" "&B110 | G110: =+G109+1 -> 110
A111: =IF(ISNA(INDEX('Yardi Report'!$A:$E,MATCH('Chart of Accounts'!$A117,'Yardi Report'!$A:$A,0),1)),"",INDEX('Yardi Report'!$A:$E,MATCH('Chart of Accounts'!$A117,'Yardi Report'!$A:$A,0),1)) | B111: =IF(ISNA(INDEX('Yardi Report'!$A:$E,MATCH('Chart of Accounts'!$A117,'Yardi Report'!$A:$A,0),2)),"",INDEX('Yardi Report'!$A:$E,MATCH('Chart of Accounts'!$A117,'Yardi Report'!$A:$A,0),2)) | C111: =IF(A111="","",MAX($C$1:C110)+1) | E111: =A111&" "&B111 | G111: =+G110+1 -> 111
A112: =IF(ISNA(INDEX('Yardi Report'!$A:$E,MATCH('Chart of Accounts'!$A118,'Yardi Report'!$A:$A,0),1)),"",INDEX('Yardi Report'!$A:$E,MATCH('Chart of Accounts'!$A118,'Yardi Report'!$A:$A,0),1)) | B112: =IF(ISNA(INDEX('Yardi Report'!$A:$E,MATCH('Chart of Accounts'!$A118,'Yardi Report'!$A:$A,0),2)),"",INDEX('Yardi Report'!$A:$E,MATCH('Chart of Accounts'!$A118,'Yardi Report'!$A:$A,0),2)) | C112: =IF(A112="","",MAX($C$1:C111)+1) | E112: =A112&" "&B112 | G112: =+G111+1 -> 112
... A467: =IF(ISNA(INDEX('Yardi Report'!$A:$E,MATCH('Chart of Accounts'!$A473,'Yardi Report'!$A:$A,0),1)),"",INDEX('Yardi Report'!$A:$E,MATCH('Chart of Accounts'!$A473,'Yardi Report'!$A:$A,0),1)) -> 2990-0000 | B467: =IF(ISNA(INDEX('Yardi Report'!$A:$E,MATCH('Chart of Accounts'!$A473,'Yardi Report'!$A:$A,0),2)),"",INDEX('Yardi Report'!$A:$E,MATCH('Chart of Accounts'!$A473,'Yardi Report'!$A:$A,0),2)) -> TOTAL LIABILITIES | C467: =IF(A467="","",MAX($C$1:C466)+1) -> 48 | E467: =A467&" "&B467 -> 2990-0000 TOTAL LIABILITIES | G467: =+G466+1 -> 467
